Workbook
Name CreditExposureData: 'Credit Exposure Register'!$A$7:$O$107
Name MigrationMatrix: 'Rating Migration Matrix'!$A$6:$J$14
Name SectorConcentration: 'Sector Concentration'!$A$5:$G$16
Name CounterpartyMaster: 'Counterparty Master'!$A$4:$J$24
Name RiskModelParams: 'Risk Model Parameters'!$A$4:$F$22

Sheet Credit Exposure Register
A1: CREDIT EXPOSURE REGISTER — Q3 2026
A2: As of Date: | B2: 46295 | D2: Prepared By: | E2: Credit Risk Analytics | H2: Reporting CCY: | I2: USD
A3: Approved By: | B3: Head of Credit Risk | D3: Status: | E3: FINAL | H3: Counterparties: | I3: 20
A6: Counterparty Information | E6: Trade Details | H6: Valuation | J6: Credit Risk Metrics | M6: Limits & Utilisation
A7: CP ID | B7: Legal Name | C7: Sector | D7: Country | E7: Trade Date | F7: Maturity Date | G7: Instrument | H7: Notional USD | I7: MTM USD | J7: PD 1Y | K7: LGD | L7: EAD USD | M7: Credit Limit USD | N7: Current Exposure USD | O7: Utilisation %
A8: CP001 | B8: Deutsche Bank AG | C8: Banking | D8: Germany | E8: 45736.771 | F8: 46264.771 | G8: Credit Default Swap | H8: 68000000 | I8: -1767028 | J8: 0.00083 | K8: 0.4656 | L8: 3400000 | M8: 2000000000 | N8: 3400000 | O8: 0.0017
A9: CP001 | B9: Deutsche Bank AG | C9: Banking | D9: Germany | E9: 45901.771 | F9: 46807.771 | G9: Senior Unsecured Bond | H9: 488000000 | I9: N/A | J9: 0.00083 | K9: 0.5146 | L9: 488000000 | M9: 2000000000 | N9: 488000000 | O9: 0.244
A10: CP001 | B10: Deutsche Bank AG | C10: Banking | D10: Germany | E10: 45810.771 | F10: 46222.771 | G10: Interest Rate Swap | H10: 292000000 | I10: 7921622 | J10: 0.00071 | K10: 0.4242 | L10: 8760000 | M10: 2000000000 | N10: 8760000 | O10: 0.00438
A11: CP001 | B11: Deutsche Bank AG | C11: Banking | D11: Germany | E11: 45924.771 | F11: 46922.771 | G11: Credit Default Swap | H11: 8000000 | I11: -133087 | J11: 0.00076 | K11: 0.4256 | L11: 400000 | M11: 2000000000 | N11: 400000 | O11: 0.0002
A12: CP001 | B12: Deutsche Bank AG | C12: Banking | D12: Germany | E12: 45760.771 | F12: 46155.771 | G12: Senior Unsecured Bond | H12: 386000000 | I12: N/A | J12: 0.00083 | K12: 0.507 | L12: 386000000 | M12: 2000000000 | N12: 386000000 | O12: 0.193
A13: CP002 | B13: BNP Paribas SA | C13: Banking | D13: France | E13: 45987.771 | F13: 46379.771 | G13: Senior Secured Loan | H13: 420000000 | I13: N/A | J13: 0.00116 | K13: 0.3049 | L13: 420000000 | M13: 1500000000 | N13: 420000000 | O13: 0.28
A14: CP002 | B14: BNP Paribas SA | C14: Banking | D14: France | E14: 45997.771 | F14: 46531.771 | G14: Trade Finance LC | H14: 248000000 | I14: N/A | J14: 0.00113 | K14: 0.2536 | L14: 124000000 | M14: 1500000000 | N14: 124000000 | O14: 0.082666667
A15: CP002 | B15: BNP Paribas SA | C15: Banking | D15: France | E15: 45872.771 | F15: 46734.771 | G15: Revolving Credit Fac. | H15: 286000000 | I15: N/A | J15: 0.00131 | K15: 0.3684 | L15: 214500000 | M15: 1500000000 | N15: 214500000 | O15: 0.143
A16: CP002 | B16: BNP Paribas SA | C16: Banking | D16: France | E16: 45900.771 | F16: 46458.771 | G16: Senior Secured Loan | H16: 257000000 | I16: N/A | J16: 0.00132 | K16: 0.3337 | L16: 257000000 | M16: 1500000000 | N16: 257000000 | O16: 0.17133333
A17: CP002 | B17: BNP Paribas SA | C17: Banking | D17: France | E17: 45826.771 | F17: 46306.771 | G17: Trade Finance LC | H17: 259000000 | I17: N/A | J17: 0.00111 | K17: 0.3482 | L17: 129500000 | M17: 1500000000 | N17: 129500000 | O17: 0.086333333
A18: CP003 | B18: HSBC Holdings plc | C18: Banking | D18: UK | E18: 45677.771 | F18: 46245.771 | G18: Senior Unsecured Bond | H18: 426000000 | I18: N/A | J18: 0.00073 | K18: 0.5054 | L18: 426000000 | M18: 1800000000 | N18: 426000000 | O18: 0.23666667
A19: CP003 | B19: HSBC Holdings plc | C19: Banking | D19: UK | E19: 45781.771 | F19: 46517.771 | G19: Interest Rate Swap | H19: 8000000 | I19: -215172 | J19: 0.00079 | K19: 0.481 | L19: 240000 | M19: 1800000000 | N19: 240000 | O19: 0.00013333333
A20: CP003 | B20: HSBC Holdings plc | C20: Banking | D20: UK | E20: 45853.771 | F20: 46673.771 | G20: Credit Default Swap | H20: 362000000 | I20: -9360195 | J20: 0.00076 | K20: 0.571 | L20: 18100000 | M20: 1800000000 | N20: 18100000 | O20: 0.010055556
A21: CP003 | B21: HSBC Holdings plc | C21: Banking | D21: UK | E21: 45816.771 | F21: 46524.771 | G21: Senior Unsecured Bond | H21: 468000000 | I21: N/A | J21: 0.0008 | K21: 0.5296 | L21: 468000000 | M21: 1800000000 | N21: 468000000 | O21: 0.26
A22: CP003 | B22: HSBC Holdings plc | C22: Banking | D22: UK | E22: 45973.771 | F22: 46589.771 | G22: Interest Rate Swap | H22: 482000000 | I22: -12291625 | J22: 0.00075 | K22: 0.4795 | L22: 14460000 | M22: 1800000000 | N22: 14460000 | O22: 0.0080333333
A23: CP004 | B23: Citibank N.A. | C23: Banking | D23: US | E23: 45670.771 | F23: 46711.771 | G23: Trade Finance LC | H23: 385000000 | I23: N/A | J23: 0.00204 | K23: 0.359 | L23: 192500000 | M23: 1200000000 | N23: 192500000 | O23: 0.16041667
A24: CP004 | B24: Citibank N.A. | C24: Banking | D24: US | E24: 45939.771 | F24: 46911.771 | G24: Revolving Credit Fac. | H24: 398000000 | I24: N/A | J24: 0.00215 | K24: 0.4286 | L24: 298500000 | M24: 1200000000 | N24: 298500000 | O24: 0.24875
A25: CP004 | B25: Citibank N.A. | C25: Banking | D25: US | E25: 45873.771 | F25: 46269.771 | G25: Senior Secured Loan | H25: 411000000 | I25: N/A | J25: 0.00171 | K25: 0.2768 | L25: 411000000 | M25: 1200000000 | N25: 411000000 | O25: 0.3425
A26: CP004 | B26: Citibank N.A. | C26: Banking | D26: US | E26: 45797.771 | F26: 46483.771 | G26: Trade Finance LC | H26: 476000000 | I26: N/A | J26: 0.00189 | K26: 0.3888 | L26: 238000000 | M26: 1200000000 | N26: 238000000 | O26: 0.19833333
A27: CP004 | B27: Citibank N.A. | C27: Banking | D27: US | E27: 45820.771 | F27: 46767.771 | G27: Revolving Credit Fac. | H27: 288000000 | I27: N/A | J27: 0.00175 | K27: 0.3218 | L27: 216000000 | M27: 1200000000 | N27: 216000000 | O27: 0.18
A28: CP005 | B28: Goldman Sachs International | C28: Inv. Banking | D28: US | E28: 45707.771 | F28: 46199.771 | G28: Interest Rate Swap | H28: 167000000 | I28: 703830 | J28: 0.00135 | K28: 0.3662 | L28: 5010000 | M28: 1000000000 | N28: 5010000 | O28: 0.00501
A29: CP005 | B29: Goldman Sachs International | C29: Inv. Banking | D29: US | E29: 45664.771 | F29: 46580.771 | G29: Credit Default Swap | H29: 105000000 | I29: 872653 | J29: 0.00136 | K29: 0.4912 | L29: 5250000 | M29: 1000000000 | N29: 5250000 | O29: 0.00525
A30: CP005 | B30: Goldman Sachs International | C30: Inv. Banking | D30: US | E30: 45895.771 | F30: 46968.771 | G30: Senior Unsecured Bond | H30: 201000000 | I30: N/A | J30: 0.00134 | K30: 0.4906 | L30: 201000000 | M30: 1000000000 | N30: 201000000 | O30: 0.201
A31: CP005 | B31: Goldman Sachs International | C31: Inv. Banking | D31: US | E31: 45973.771 | F31: 46666.771 | G31: Interest Rate Swap | H31: 369000000 | I31: -5353324 | J31: 0.00145 | K31: 0.3561 | L31: 11070000 | M31: 1000000000 | N31: 11070000 | O31: 0.01107
A32: CP005 | B32: Goldman Sachs International | C32: Inv. Banking | D32: US | E32: 45857.771 | F32: 46778.771 | G32: Credit Default Swap | H32: 100000000 | I32: 1444789 | J32: 0.00171 | K32: 0.5528 | L32: 5000000 | M32: 1000000000 | N32: 5000000 | O32: 0.005
A33: CP006 | B33: Mitsubishi UFJ Financial | C33: Banking | D33: Japan | E33: 45874.771 | F33: 46590.771 | G33: Revolving Credit Fac. | H33: 70000000 | I33: N/A | J33: 0.00239 | K33: 0.3165 | L33: 52500000 | M33: 900000000 | N33: 52500000 | O33: 0.058333333
A34: CP006 | B34: Mitsubishi UFJ Financial | C34: Banking | D34: Japan | E34: 45796.771 | F34: 46236.771 | G34: Senior Secured Loan | H34: 22000000 | I34: N/A | J34: 0.0028 | K34: 0.3001 | L34: 22000000 | M34: 900000000 | N34: 22000000 | O34: 0.024444444
A35: CP006 | B35: Mitsubishi UFJ Financial | C35: Banking | D35: Japan | E35: 45986.771 | F35: 46618.771 | G35: Trade Finance LC | H35: 310000000 | I35: N/A | J35: 0.0024 | K35: 0.3949 | L35: 155000000 | M35: 900000000 | N35: 155000000 | O35: 0.17222222
A36: CP006 | B36: Mitsubishi UFJ Financial | C36: Banking | D36: Japan | E36: 46003.771 | F36: 46518.771 | G36: Revolving Credit Fac. | H36: 325000000 | I36: N/A | J36: 0.0023 | K36: 0.321 | L36: 243750000 | M36: 900000000 | N36: 243750000 | O36: 0.27083333
A37: CP006 | B37: Mitsubishi UFJ Financial | C37: Banking | D37: Japan | E37: 45662.771 | F37: 46252.771 | G37: Senior Secured Loan | H37: 366000000 | I37: N/A | J37: 0.0026 | K37: 0.2406 | L37: 366000000 | M37: 900000000 | N37: 366000000 | O37: 0.40666667
A38: CP007 | B38: Apple Inc | C38: Technology | D38: US | E38: 45719.771 | F38: 46583.771 | G38: Credit Default Swap | H38: 204000000 | I38: 1405843 | J38: 0.0002 | K38: 0.4904 | L38: 10200000 | M38: 500000000 | N38: 10200000 | O38: 0.0204
A39: CP007 | B39: Apple Inc | C39: Technology | D39: US | E39: 45707.771 | F39: 46649.771 | G39: Senior Unsecured Bond | H39: 198000000 | I39: N/A | J39: 0.0002 | K39: 0.4585 | L39: 198000000 | M39: 500000000 | N39: 198000000 | O39: 0.396
A40: CP007 | B40: Apple Inc | C40: Technology | D40: US | E40: 45822.771 | F40: 46421.771 | G40: Interest Rate Swap | H40: 365000000 | I40: 6116061 | J40: 0.00017 | K40: 0.4277 | L40: 10950000 | M40: 500000000 | N40: 10950000 | O40: 0.0219
A41: CP007 | B41: Apple Inc | C41: Technology | D41: US | E41: 45696.771 | F41: 46274.771 | G41: Credit Default Swap | H41: 197000000 | I41: 2302052 | J41: 0.00021 | K41: 0.4697 | L41: 9850000 | M41: 500000000 | N41: 9850000 | O41: 0.0197
A42: CP007 | B42: Apple Inc | C42: Technology | D42: US | E42: 45749.771 | F42: 46208.771 | G42: Senior Unsecured Bond | H42: 158000000 | I42: N/A | J42: 0.00023 | K42: 0.51 | L42: 158000000 | M42: 500000000 | N42: 158000000 | O42: 0.316
...

Sheet Rating Migration Matrix
A1: 1-YEAR RATING MIGRATION MATRIX — MOODY'S SCALE (2023 ANNUAL STUDY)
A2: Source: | B2: Moody's Annual Default & Rating Transition Study 2023
A3: Usage: | B3: Internal credit migration scenario modelling — restricted, not for external distribution
A4: Row = Starting Rating | Column = Ending Rating | Values = 1-year transition probability
A6: From \ To | B6: AAA | C6: AA | D6: A | E6: BBB | F6: BB | G6: B | H6: CCC | I6: D (Default) | J6: Row Sum
A7: AAA | B7: 0.9241 | C7: 0.0634 | D7: 0.006 | E7: 0.0013 | F7: 0.0006 | G7: 0.0003 | H7: 0.0002 | I7: 0.0001 | J7: =SUM(B7:I7)
A8: AA | B8: 0.0072 | C8: 0.9072 | D8: 0.077 | E8: 0.0058 | F8: 0.0013 | G8: 0.0009 | H8: 0.0002 | I8: 0.0004 | J8: =SUM(B8:I8)
A9: A | B9: 0.0009 | C9: 0.0222 | D9: 0.9078 | E9: 0.0603 | F9: 0.0063 | G9: 0.0017 | H9: 0.0003 | I9: 0.0005 | J9: =SUM(B9:I9)
A10: BBB | B10: 0.0004 | C10: 0.0034 | D10: 0.0541 | E10: 0.879 | F10: 0.0493 | G10: 0.0105 | H10: 0.0019 | I10: 0.0014 | J10: =SUM(B10:I10)
A11: BB | B11: 0.0003 | C11: 0.0013 | D11: 0.0068 | E11: 0.0687 | F11: 0.801 | G11: 0.0985 | H11: 0.0122 | I11: 0.0112 | J11: =SUM(B11:I11)
A12: B | B12: 0.0001 | C12: 0.0006 | D12: 0.005 | E12: 0.015 | F12: 0.078 | G12: 0.8154 | H12: 0.0629 | I12: 0.023 | J12: =SUM(B12:I12)
A13: CCC | B13: 0.0001 | C13: 0.0003 | D13: 0.0023 | E13: 0.0065 | F13: 0.0182 | G13: 0.0989 | H13: 0.6279 | I13: 0.2458 | J13: =SUM(B13:I13)
A14: D (Default) | B14: 0 | C14: 0 | D14: 0 | E14: 0 | F14: 0 | G14: 0 | H14: 0 | I14: 1 | J14: =SUM(B14:I14)
A16: Note: Row sums should equal 100.00%. Diagonal entries (shaded) represent probability of rating stability.

Sheet Sector Concentration
A1: CREDIT EXPOSURE BY SECTOR — Q3 2026 SUMMARY
A2: Source: Credit Exposure Register (live SUMIF/COUNTIF — auto-recalculates on workbook open)
B4: Volume Metrics | E4: Risk Indicators
A5: Sector | B5: Trade Count | C5: Total Notional USD | D5: Total EAD USD | E5: Avg PD 1Y | F5: Avg LGD | G5: Exposure Share %
A6: Banking | B6: =COUNTIF('Credit Exposure Register'!C:C,"Banking") | C6: =SUMIF('Credit Exposure Register'!C:C,"Banking",'Credit Exposure Register'!H:H) | D6: =SUMIF('Credit Exposure Register'!C:C,"Banking",'Credit Exposure Register'!L:L) | E6: =AVERAGEIF('Credit Exposure Register'!C:C,"Banking",'Credit Exposure Register'!J:J) | F6: =AVERAGEIF('Credit Exposure Register'!C:C,"Banking",'Credit Exposure Register'!K:K) | G6: =D6/SUM($D$6:$D$16)
A7: Inv. Banking | B7: =COUNTIF('Credit Exposure Register'!C:C,"Inv. Banking") | C7: =SUMIF('Credit Exposure Register'!C:C,"Inv. Banking",'Credit Exposure Register'!H:H) | D7: =SUMIF('Credit Exposure Register'!C:C,"Inv. Banking",'Credit Exposure Register'!L:L) | E7: =AVERAGEIF('Credit Exposure Register'!C:C,"Inv. Banking",'Credit Exposure Register'!J:J) | F7: =AVERAGEIF('Credit Exposure Register'!C:C,"Inv. Banking",'Credit Exposure Register'!K:K) | G7: =D7/SUM($D$6:$D$16)
A8: Technology | B8: =COUNTIF('Credit Exposure Register'!C:C,"Technology") | C8: =SUMIF('Credit Exposure Register'!C:C,"Technology",'Credit Exposure Register'!H:H) | D8: =SUMIF('Credit Exposure Register'!C:C,"Technology",'Credit Exposure Register'!L:L) | E8: =AVERAGEIF('Credit Exposure Register'!C:C,"Technology",'Credit Exposure Register'!J:J) | F8: =AVERAGEIF('Credit Exposure Register'!C:C,"Technology",'Credit Exposure Register'!K:K) | G8: =D8/SUM($D$6:$D$16)
A9: Energy | B9: =COUNTIF('Credit Exposure Register'!C:C,"Energy") | C9: =SUMIF('Credit Exposure Register'!C:C,"Energy",'Credit Exposure Register'!H:H) | D9: =SUMIF('Credit Exposure Register'!C:C,"Energy",'Credit Exposure Register'!L:L) | E9: =AVERAGEIF('Credit Exposure Register'!C:C,"Energy",'Credit Exposure Register'!J:J) | F9: =AVERAGEIF('Credit Exposure Register'!C:C,"Energy",'Credit Exposure Register'!K:K) | G9: =D9/SUM($D$6:$D$16)
A10: Healthcare | B10: =COUNTIF('Credit Exposure Register'!C:C,"Healthcare") | C10: =SUMIF('Credit Exposure Register'!C:C,"Healthcare",'Credit Exposure Register'!H:H) | D10: =SUMIF('Credit Exposure Register'!C:C,"Healthcare",'Credit Exposure Register'!L:L) | E10: =AVERAGEIF('Credit Exposure Register'!C:C,"Healthcare",'Credit Exposure Register'!J:J) | F10: =AVERAGEIF('Credit Exposure Register'!C:C,"Healthcare",'Credit Exposure Register'!K:K) | G10: =D10/SUM($D$6:$D$16)
A11: Automotive | B11: =COUNTIF('Credit Exposure Register'!C:C,"Automotive") | C11: =SUMIF('Credit Exposure Register'!C:C,"Automotive",'Credit Exposure Register'!H:H) | D11: =SUMIF('Credit Exposure Register'!C:C,"Automotive",'Credit Exposure Register'!L:L) | E11: =AVERAGEIF('Credit Exposure Register'!C:C,"Automotive",'Credit Exposure Register'!J:J) | F11: =AVERAGEIF('Credit Exposure Register'!C:C,"Automotive",'Credit Exposure Register'!K:K) | G11: =D11/SUM($D$6:$D$16)
A12: Insurance | B12: =COUNTIF('Credit Exposure Register'!C:C,"Insurance") | C12: =SUMIF('Credit Exposure Register'!C:C,"Insurance",'Credit Exposure Register'!H:H) | D12: =SUMIF('Credit Exposure Register'!C:C,"Insurance",'Credit Exposure Register'!L:L) | E12: =AVERAGEIF('Credit Exposure Register'!C:C,"Insurance",'Credit Exposure Register'!J:J) | F12: =AVERAGEIF('Credit Exposure Register'!C:C,"Insurance",'Credit Exposure Register'!K:K) | G12: =D12/SUM($D$6:$D$16)
A13: Utilities | B13: =COUNTIF('Credit Exposure Register'!C:C,"Utilities") | C13: =SUMIF('Credit Exposure Register'!C:C,"Utilities",'Credit Exposure Register'!H:H) | D13: =SUMIF('Credit Exposure Register'!C:C,"Utilities",'Credit Exposure Register'!L:L) | E13: =AVERAGEIF('Credit Exposure Register'!C:C,"Utilities",'Credit Exposure Register'!J:J) | F13: =AVERAGEIF('Credit Exposure Register'!C:C,"Utilities",'Credit Exposure Register'!K:K) | G13: =D13/SUM($D$6:$D$16)
A14: Retail | B14: =COUNTIF('Credit Exposure Register'!C:C,"Retail") | C14: =SUMIF('Credit Exposure Register'!C:C,"Retail",'Credit Exposure Register'!H:H) | D14: =SUMIF('Credit Exposure Register'!C:C,"Retail",'Credit Exposure Register'!L:L) | E14: =AVERAGEIF('Credit Exposure Register'!C:C,"Retail",'Credit Exposure Register'!J:J) | F14: =AVERAGEIF('Credit Exposure Register'!C:C,"Retail",'Credit Exposure Register'!K:K) | G14: =D14/SUM($D$6:$D$16)
A15: Telecom | B15: =COUNTIF('Credit Exposure Register'!C:C,"Telecom") | C15: =SUMIF('Credit Exposure Register'!C:C,"Telecom",'Credit Exposure Register'!H:H) | D15: =SUMIF('Credit Exposure Register'!C:C,"Telecom",'Credit Exposure Register'!L:L) | E15: =AVERAGEIF('Credit Exposure Register'!C:C,"Telecom",'Credit Exposure Register'!J:J) | F15: =AVERAGEIF('Credit Exposure Register'!C:C,"Telecom",'Credit Exposure Register'!K:K) | G15: =D15/SUM($D$6:$D$16)
A16: Mining | B16: =COUNTIF('Credit Exposure Register'!C:C,"Mining") | C16: =SUMIF('Credit Exposure Register'!C:C,"Mining",'Credit Exposure Register'!H:H) | D16: =SUMIF('Credit Exposure Register'!C:C,"Mining",'Credit Exposure Register'!L:L) | E16: =AVERAGEIF('Credit Exposure Register'!C:C,"Mining",'Credit Exposure Register'!J:J) | F16: =AVERAGEIF('Credit Exposure Register'!C:C,"Mining",'Credit Exposure Register'!K:K) | G16: =D16/SUM($D$6:$D$16)
A17: TOTAL | B17: =SUM(B6:B16) | C17: =SUM(C6:C16) | D17: =SUM(D6:D16) | G17: =SUM(G6:G16)
A19: * Avg PD and Avg LGD use AVERAGEIF — sectors with zero trades show #DIV/0 (expected, not an error)

Sheet Counterparty Master
A1: COUNTERPARTY MASTER — APPROVED CREDIT COUNTERPARTIES
A2: Last Review Date: | B2: 46235 | D2: Approved By: | E2: Credit Committee | H2: Next Review: | I2: 46419
A4: CP ID | B4: Legal Name | C4: Short Name | D4: Sector | E4: Country | F4: Internal Rating | G4: External Rating | H4: Credit Limit USD | I4: Onboarding Date | J4: Status
A5: CP001 | B5: Deutsche Bank AG | C5: Deutsche | D5: Banking | E5: Germany | F5: AA- | G5: AA- | H5: 2000000000 | I5: 43100.771 | J5: ACTIVE
A6: CP002 | B6: BNP Paribas SA | C6: BNP | D6: Banking | E6: France | F6: A+ | G6: A+ | H6: 1500000000 | I6: 43131.771 | J6: ACTIVE
A7: CP003 | B7: HSBC Holdings plc | C7: HSBC | D7: Banking | E7: UK | F7: AA- | G7: AA- | H7: 1800000000 | I7: 43159.771 | J7: ACTIVE
A8: CP004 | B8: Citibank N.A. | C8: Citibank | D8: Banking | E8: US | F8: A | G8: A | H8: 1200000000 | I8: 43190.771 | J8: ACTIVE
A9: CP005 | B9: Goldman Sachs International | C9: Goldman | D9: Inv. Banking | E9: US | F9: A+ | G9: A+ | H9: 1000000000 | I9: 43220.771 | J9: ACTIVE
A10: CP006 | B10: Mitsubishi UFJ Financial | C10: Mitsubishi | D10: Banking | E10: Japan | F10: A- | G10: A- | H10: 900000000 | I10: 43616.771 | J10: ACTIVE
A11: CP007 | B11: Apple Inc | C11: Apple | D11: Technology | E11: US | F11: AAA | G11: AAA | H11: 500000000 | I11: 43646.771 | J11: ACTIVE
A12: CP008 | B12: Shell plc | C12: Shell | D12: Energy | E12: UK | F12: AA | G12: AA | H12: 750000000 | I12: 43677.771 | J12: ACTIVE
A13: CP009 | B13: AstraZeneca plc | C13: AstraZeneca | D13: Healthcare | E13: UK | F13: A+ | G13: A+ | H13: 400000000 | I13: 43708.771 | J13: ACTIVE
A14: CP010 | B14: Volkswagen AG | C14: Volkswagen | D14: Automotive | E14: Germany | F14: BBB+ | G14: BBB+ | H14: 600000000 | I14: 43738.771 | J14: REVIEW
A15: CP011 | B15: Allianz SE | C15: Allianz | D15: Insurance | E15: Germany | F15: AA | G15: AA | H15: 800000000 | I15: 44135.771 | J15: ACTIVE
A16: CP012 | B16: Berkshire Hathaway Finance | C16: Berkshire | D16: Insurance | E16: US | F16: AA+ | G16: AA+ | H16: 1000000000 | I16: 44165.771 | J16: ACTIVE
... A24: CP020 | B24: Westpac Banking Corp | C24: Westpac | D24: Banking | E24: Australia | F24: A- | G24: A- | H24: 600000000 | I24: 44408.771 | J24: ACTIVE

Sheet Risk Model Parameters
A1: CREDIT RISK MODEL PARAMETERS & GOVERNANCE RECORD
A2: All parameter changes require Credit Risk Committee approval and must be logged in the model change register.
A4: Parameter | B4: Value | C4: Unit | D4: Last Updated | E4: Approved By | F4: Notes
A5: VaR Confidence Level | B5: 99% | C5: Percent | D5: 46023 | E5: CRC-2026-01 | F5: Basel III minimum 99% for internal models approach (IMA)
A6: VaR Holding Period | B6: 10 | C6: Business Days | D6: 46023 | E6: CRC-2026-01 | F6: Regulatory capital square root of time scaling from 1-day VaR
A7: Credit VaR Horizon | B7: 1 | C7: Year | D7: 46023 | E7: CRC-2026-01 | F7: Annual horizon used for ICAAP credit VaR and stress testing
A8: PD Floor — Investment Grade | B8: 0.0300% | C8: Percent | D8: 46096 | E8: CRC-2026-07 | F8: Minimum PD for BBB- and above per CRR III Art. 160
A9: PD Floor — Sub-Investment Grade | B9: 0.1000% | C9: Percent | D9: 46096 | E9: CRC-2026-07 | F9: Minimum PD for BB+ and below per CRR III Art. 160
A10: LGD Floor — Senior Secured | B10: 20% | C10: Percent | D10: 46023 | E10: CRC-2026-01 | F10: F-IRB LGD floor for collateralised exposures
A11: LGD Floor — Senior Unsecured | B11: 45% | C11: Percent | D11: 46023 | E11: CRC-2026-01 | F11: F-IRB LGD for unsecured senior corporate per Basel
A12: Asset Correlation — Corporate | B12: 12%–24% | C12: Range | D12: 46023 | E12: CRC-2026-01 | F12: Basel III supervisory formula; higher for low-PD obligors
A13: Concentration Threshold | B13: 5% | C13: Percent | D13: 46174 | E13: CRC-2026-12 | F13: Sector concentration >5% of total EAD triggers capital add-on
A14: High Utilisation Threshold | B14: 80% | C14: Percent | D14: 46023 | E14: CRC-2026-01 | F14: Exposures >80% of limit trigger enhanced monitoring review
A15: Hard Limit Breach Threshold | B15: 100% | C15: Percent | D15: 46023 | E15: CRC-2026-01 | F15: >100% requires immediate escalation to CRO and CFO
A16: Migration Model Source | B16: Moody's 2023 | C16: N/A | D16: 46204 | E16: CRC-2026-15 | F16: Annual transition matrix — updated each July with Moody's new study
... A21: Recovery Rate — Corporate (Secured) | B21: 65% | C21: Percent | D21: 46023 | E21: CRC-2026-01 | F21: Senior secured recovery for corporate counterparties
A22: Model Next Validation Date | B22: 46477 | C22: Date | D22: 46266 | E22: CRC-2026-18 | F22: Annual model validation cycle — mandatory per SR 11-7 / SS1/23
